Workbook

Sheet Existencia Sistema
A1: MULTINACIONAL DE SABORES C.A. | E1: PRODUCIR | J1: =TODAY() -> 46323
A2: EXISTENCIA FISICA MULTINACIONAL | E2: NO PRODUCIR | J2: 0.35416667
A3: Almacenes consolidados: NoAlmacén: Principal | E3: POR DECISION
A4: Artículo | B4: Denominación | C4: Cajas / Paleta | E4: Stock | G4: UND | H4: PALETAS | I4: CONSUMO PROM PALETAS X DIA | J4: DIAS INVENTARIO PARA CONSUMO
A5: PRODT-0007 | B5: GLUP! COLA NEGRA 6X2000ML | C5: 80 | E5: =VLOOKUP(A5,'Existencia Sistemaac'!$A$13:$AJ$90,10,FALSE) -> 76189 | G5: CJ | H5: =+E5/C5 -> 952.3625 | I5: 804 | J5: =IFERROR(ROUND((+H5/I5),1),0) -> 1.2
A6: PRODT-0008 | B6: GLUP! UVA 6X2000ML | C6: 80 | E6: =VLOOKUP(A6,'Existencia Sistemaac'!$A$13:$AJ$90,10,FALSE) -> 23648 | G6: CJ | H6: =+E6/C6 -> 295.6 | I6: 111 | J6: =IFERROR(ROUND((+H6/I6),1),0) -> 2.7
A7: PRODT-0009 | B7: GLUP! KOLITA 6X2000ML | C7: 80 | E7: =VLOOKUP(A7,'Existencia Sistemaac'!$A$13:$AJ$90,10,FALSE) -> 56226 | G7: CJ | H7: =+E7/C7 -> 702.825 | I7: 240 | J7: =IFERROR(ROUND((+H7/I7),1),0) -> 2.9
A8: PRODT-0010 | B8: GLUP! PIÑA 6X2000ML | C8: 80 | E8: =VLOOKUP(A8,'Existencia Sistemaac'!$A$13:$AJ$90,10,FALSE) -> 2192 | G8: CJ | H8: =+E8/C8 -> 27.4 | I8: 83 | J8: =IFERROR(ROUND((+H8/I8),1),0) -> 0.3
A9: PRODT-0011 | B9: GLUP! NARANJA 6X2000ML | C9: 80 | E9: =VLOOKUP(A9,'Existencia Sistemaac'!$A$13:$AJ$90,10,FALSE) -> 0 | G9: CJ | H9: =+E9/C9 -> 0 | I9: 86 | J9: =IFERROR(ROUND((+H9/I9),1),0) -> 0
A10: PRODT-0012 | B10: GLUP! FRESH 6X2000ML | C10: 80 | E10: =VLOOKUP(A10,'Existencia Sistemaac'!$A$13:$AJ$90,10,FALSE) -> 25637 | G10: CJ | H10: =+E10/C10 -> 320.4625 | I10: 261 | J10: =IFERROR(ROUND((+H10/I10),1),0) -> 1.2
A11: PRODT-0049 | B11: GLUP! MANZANA VERDE CAJA X 6BOT X 2LTS | C11: 80 | E11: =VLOOKUP(A11,'Existencia Sistemaac'!$A$13:$AJ$90,10,FALSE) -> 15612 | G11: CJ | H11: =+E11/C11 -> 195.15 | I11: 6 | J11: =IFERROR(ROUND((+H11/I11),1),0) -> 32.5
A12: PRODT-0097 | B12: GLUP! MANZANA ROJA CAJA X 6BOT X 2.0LTS | C12: 80 | E12: =VLOOKUP(A12,'Existencia Sistemaac'!$A$13:$AJ$90,10,FALSE) -> 7068 | G12: CJ | H12: =+E12/C12 -> 88.35 | I12: 60 | J12: =IFERROR(ROUND((+H12/I12),1),0) -> 1.5
A13: PRODT-0098 | B13: GLUP! PIÑA PARCHITA CAJA X 6BOT X 2.0LTS | C13: 80 | E13: =VLOOKUP(A13,'Existencia Sistemaac'!$A$13:$AJ$90,10,FALSE) -> 6075 | G13: CJ | H13: =+E13/C13 -> 75.9375 | I13: 6 | J13: =IFERROR(ROUND((+H13/I13),1),0) -> 12.7
A14: PRODT-0082 | B14: GLUP! COLA NEGRA CAJA X 12BOT X 1LTS | C14: 78 | E14: =VLOOKUP(A14,'Existencia Sistemaac'!$A$13:$AJ$90,10,FALSE) -> 9650 | G14: CJ | H14: =+E14/C14 -> 123.71795 | I14: 118 | J14: =IFERROR(ROUND((+H14/I14),1),0) -> 1
A15: PRODT-0084 | B15: GLUP! UVA CAJA X 12BOT X 1.0LTS | C15: 78 | E15: =VLOOKUP(A15,'Existencia Sistemaac'!$A$13:$AJ$90,10,FALSE) -> 9523 | G15: CJ | H15: =+E15/C15 -> 122.08974 | I15: 14 | J15: =IFERROR(ROUND((+H15/I15),1),0) -> 8.7
A16: PRODT-0086 | B16: GLUP! FRESH CAJA X 12BOT X 1.0LTS | C16: 78 | E16: =VLOOKUP(A16,'Existencia Sistemaac'!$A$13:$AJ$90,10,FALSE) -> 4681 | G16: CJ | H16: =+E16/C16 -> 60.012821 | I16: 49 | J16: =IFERROR(ROUND((+H16/I16),1),0) -> 1.2
... A43: PRODT-0122 | B43: POWER X SABOR NARANJA CAJA X 15BOT X 0.400LTS | C43: 160 | E43: =VLOOKUP(A43,'Existencia Sistemaac'!$A$13:$AJ$90,10,FALSE) -> 0 | G43: CJ | H43: =+E43/C43 -> 0 | I43: 0 | J43: =IFERROR(ROUND((+H43/I43),1),0) -> 0
E45: =SUM(E5:E44) -> 388009 | H45: =SUM(H5:H44) -> 4613.4754

Sheet Existencia Sistemaac
A1: MULTINACIONAL DE SABORES C.A. | D1: Área: PRINCIPAL | J1: PRODUCIR | AJ1: 46323
A2: EXISTENCIA FISICA MULTINACIONAL | J2: NO PRODUCIR | AJ2: 0.33333333
A3: Almacenes consolidados: NoAlmacén: Principal | J3: POR DECISION
B4: Del almacén: 100
B5: Artículo: <Todos>
B6: Denominación: <Todos>
B7: Tipo: 70
B8: Clase: <Todos>
B9: Grupo: <Todos>
B10: Familia: <Todos>
B11: Limitar disponible: No
B12: Considerar únicamente MP y subcontratación: No
A13: Artículo | B13: Denominación | H13: Cajas / Paleta | J13: Stock | L13: UND | M13: ACUMULADO PLASTIMAX, C.A. | N13: SAP | O13: dif FISICO | P13: PLASTIMAX, C.A. DEL DIA ACTUAL | Q13: PALETAS | AI13: CONSUMO PROM PALETAS X DIA | AJ13: DIAS INVENTARIO PARA CONSUMO
A14: PRODT-0001 | B14: GLUP! COLA NEGRA 12X1500ML | H14: 70 | J14: =+IFERROR(VLOOKUP(A14,$R$26:$U$119,4,FALSE),0) -> 0 | L14: CJ | M14: =+J14-N14 -> 0 | N14: =+J14 -> 0 | P14: =J14-IFERROR(VLOOKUP(A14,$R$26:$U$119,4,FALSE),0)+0 -> 0 | AC14: =+IFERROR(VLOOKUP(T14,$R$26:$U$119,4,FALSE),0) -> 0
A15: PRODT-0002 | B15: GLUP! UVA 12X1500ML | H15: 70 | J15: =+IFERROR(VLOOKUP(A15,$R$26:$U$119,4,FALSE),0) -> 0 | L15: CJ | M15: =+J15-N15 -> 0 | N15: =+J15 -> 0 | P15: =J15-IFERROR(VLOOKUP(A15,$R$26:$U$119,4,FALSE),0)+0 -> 0 | AC15: =+IFERROR(VLOOKUP(T15,$R$26:$U$119,4,FALSE),0) -> 0
A16: PRODT-0003 | B16: GLUP! KOLITA 12X1500ML | H16: 70 | J16: =+IFERROR(VLOOKUP(A16,$R$26:$U$119,4,FALSE),0) -> 0 | L16: CJ | M16: =+J16-N16 -> 0 | N16: =+J16 -> 0 | P16: =J16-IFERROR(VLOOKUP(A16,$R$26:$U$119,4,FALSE),0)+0 -> 0 | AC16: =+IFERROR(VLOOKUP(T16,$R$26:$U$119,4,FALSE),0) -> 0
A17: PRODT-0004 | B17: GLUP! PIÑA 12X1500ML | H17: 70 | J17: =+IFERROR(VLOOKUP(A17,$R$26:$U$119,4,FALSE),0) -> 0 | L17: CJ | M17: =+J17-N17 -> 0 | N17: =+J17 -> 0 | P17: =J17-IFERROR(VLOOKUP(A17,$R$26:$U$119,4,FALSE),0)+0 -> 0 | AC17: =+IFERROR(VLOOKUP(T17,$R$26:$U$119,4,FALSE),0) -> 0
A18: PRODT-0005 | B18: GLUP! NARANJA 12X1500ML | H18: 70 | J18: =+IFERROR(VLOOKUP(A18,$R$26:$U$119,4,FALSE),0) -> 0 | L18: CJ | M18: =+J18-N18 -> 0 | N18: =+J18 -> 0 | P18: =J18-IFERROR(VLOOKUP(A18,$R$26:$U$119,4,FALSE),0)+0 -> 0 | AC18: =+IFERROR(VLOOKUP(T24,$R$26:$U$119,4,FALSE),0) -> 0
A19: PRODT-0006 | B19: GLUP! FRESH 12X1500ML | H19: 70 | J19: =+IFERROR(VLOOKUP(A19,$R$26:$U$119,4,FALSE),0) -> 0 | L19: CJ | M19: =+J19-N19 -> 0 | N19: =+J19 -> 0 | P19: =J19-IFERROR(VLOOKUP(A19,$R$26:$U$119,4,FALSE),0)+0 -> 0 | AC19: =+IFERROR(VLOOKUP(T25,$R$26:$U$119,4,FALSE),0) -> 0
A20: PRODT-0039 | B20: GLUP! COLA NEGRA CAJA X 6BOT X 1.5LTS | H20: 70 | J20: =+IFERROR(VLOOKUP(A20,$R$24:$U$119,4,FALSE),0) -> 0 | L20: CJ | M20: =+J20-N20 -> 0 | N20: =+IFERROR(VLOOKUP(A20,$R$26:$U$119,4,FALSE),0)-0 -> 0 | P20: =J20-IFERROR(VLOOKUP(A20,$R$26:$U$119,4,FALSE),0)+0 -> 0
A21: PRODT-0045 | B21: GLUP! PONCHE DE FRUTAS CAJA X 12BOT X 1.5LTS | H21: 70 | J21: =+IFERROR(VLOOKUP(A21,$R$24:$U$119,4,FALSE),0) -> 0 | L21: CJ | M21: =+J21-N21 -> 0 | N21: =+IFERROR(VLOOKUP(A21,$R$26:$U$119,4,FALSE),0)-0 -> 0 | P21: =J21-IFERROR(VLOOKUP(A21,$R$26:$U$119,4,FALSE),0)+0 -> 0
A22: PRODT-0046 | B22: GLUP! MANZANA VERDE CAJA X 12BOT X 1.5LTS | H22: 70 | J22: =+IFERROR(VLOOKUP(A22,$R$24:$U$119,4,FALSE),0) -> 0 | L22: CJ | M22: =+J22-N22 -> 0 | N22: =+IFERROR(VLOOKUP(A22,$R$26:$U$119,4,FALSE),0)-0 -> 0 | P22: =J22-IFERROR(VLOOKUP(A22,$R$26:$U$119,4,FALSE),0)+0 -> 0
A23: PRODT-0047 | B23: GLUP! CHICLE BOMBA CAJA X 12BOT X 1.5LTS | H23: 70 | J23: =+IFERROR(VLOOKUP(A23,$R$24:$U$119,4,FALSE),0) -> 0 | L23: CJ | M23: =+J23-N23 -> 0 | N23: =+IFERROR(VLOOKUP(A23,$R$26:$U$119,4,FALSE),0)-0 -> 0 | P23: =J23-IFERROR(VLOOKUP(A23,$R$26:$U$119,4,FALSE),0)+0 -> 0
A24: PRODT-0007 | B24: GLUP! COLA NEGRA 6X2000ML | H24: 80 | J24: =44419-1+13451+18320 -> 76189 | L24: CJ | M24: =+J24-N24 -> 76189 | N24: =+IFERROR(VLOOKUP(A24,$R$26:$U$119,4,FALSE),0)-0 -> 0 | O24: =51208-J24 -> -24981 | P24: =J24-IFERROR(VLOOKUP(A24,$R$26:$U$119,4,FALSE),0)+19600 -> 95789 | Q24: =+J24/H24 -> 952.3625 | R24: PRODT-0007 | S24: GLUP! COLA NEGRA CAJA X 6BOT X 2.0LTS | T24: CAJA | U24: 69558 | V24: 126132 | X24: -23035 | Y24: USD 1,680 | Z24: USD 173.202,960 | AC24: =+IFERROR(VLOOKUP(T24,$R$24:$U$119,4,FALSE),0)-0-5920-5920-7520-9040-4640-4240-5440-4160-8720 -> -55600 | AE24: =1+99+8+88+240+256+10+48+64+21+56+116+160+80+336+1 -> 1584 | AF24: =+AE24*80 -> 126720 | AG24: =+AF24+54+48 -> 126822 | AI24: 804 | AJ24: =IFERROR(ROUND((+Q24/AI24),1),0) -> 1.2 | AN24: ACTUALIZADO SEPTIEMBRE 2026
A25: PRODT-0008 | B25: GLUP! UVA 6X2000ML | H25: 80 | J25: =23488+160 -> 23648 | L25: CJ | M25: =+J25-N25 -> 23648 | N25: =+IFERROR(VLOOKUP(A25,$R$26:$U$119,4,FALSE),0)-0 -> 0 | O25: =204-J25 -> -23444 | P25: =J25-IFERROR(VLOOKUP(A25,$R$26:$U$119,4,FALSE),0)+0 -> 23648 | Q25: =+J25/H25 -> 295.6 | R25: PRODT-0008 | S25: GLUP! UVA CAJA X 6BOT X 2.0LTS | T25: CAJA | U25: 26276 | V25: 6395 | X25: 7324 | Y25: USD 1,680 | Z25: USD 23.047,920 | AC25: =+IFERROR(VLOOKUP(T25,$R$24:$U$119,4,FALSE),0)-0-2480-2560-1280-480-960-640-160 -> -8560 | AE25: =1+29+96+88+56+12+0 -> 282 | AF25: =+AE25*80 -> 22560 | AG25: =+AF25+44+18 -> 22622 | AI25: 111 | AJ25: =IFERROR(ROUND((+Q25/AI25),1),0) -> 2.7
A26: PRODT-0009 | B26: GLUP! KOLITA 6X2000ML | H26: 80 | J26: =34826+21400 -> 56226 | L26: CJ | M26: =+J26-N26 -> 32810 | N26: =+IFERROR(VLOOKUP(A26,$R$26:$U$119,4,FALSE),0)-0 -> 23416 | O26: =8449-J26 -> -47777 | P26: =J26-IFERROR(VLOOKUP(A26,$R$26:$U$119,4,FALSE),0)+5120 -> 37930 | Q26: =+J26/H26 -> 702.825 | R26: PRODT-0009 | S26: GLUP! KOLITA CAJA X 6BOT X 2.0LTS | T26: CAJA | U26: 23416 | V26: 17820 | X26: -8915 | Y26: USD 1,680 | Z26: USD 14.960,400 | AC26: =+IFERROR(VLOOKUP(T26,$R$24:$U$119,4,FALSE),0)-0-160-3520-4720-3360-480-2880-3200 -> -18320 | AE26: =34+116+144+18+0 -> 312 | AF26: =+AE26*50 -> 15600 | AG26: =+AF26+3+28 -> 15631 | AI26: 240 | AJ26: =IFERROR(ROUND((+Q26/AI26),1),0) -> 2.9
A27: PRODT-0010 | B27: GLUP! PIÑA 6X2000ML | H27: 80 | J27: =32+2160 -> 2192 | L27: CJ | M27: =+J27-N27 -> 2189 | N27: =+IFERROR(VLOOKUP(A27,$R$26:$U$119,4,FALSE),0)-0 -> 3 | O27: =5605-J27 -> 3413 | P27: =J27-IFERROR(VLOOKUP(A27,$R$26:$U$119,4,FALSE),0)+4720+0 -> 6909 | Q27: =+J27/H27 -> 27.4 | R27: PRODT-0010 | S27: GLUP! PIÑA CAJA X 6BOT X 2.0LTS | T27: CAJA | U27: 3 | V27: 7320 | X27: 17629 | Y27: USD 1,680 | Z27: USD 41.914,320 | AC27: =+IFERROR(VLOOKUP(T27,$R$24:$U$119,4,FALSE),0)-0-4160 -> -4160 | AE27: =20+38+1+144+93+0 -> 296 | AF27: =+AE27*80 -> 23680 | AG27: =+AF27+48+1 -> 23729 | AI27: 83 | AJ27: =IFERROR(ROUND((+Q27/AI27),1),0) -> 0.3
A28: PRODT-0011 | B28: GLUP! NARANJA 6X2000ML | H28: 80 | J28: 0 | L28: CJ | M28: =+J28-N28 -> 0 | N28: =+IFERROR(VLOOKUP(A28,$R$26:$U$119,4,FALSE),0)-0 -> 0 | O28: =0-J28 -> 0 | P28: =J28-IFERROR(VLOOKUP(A28,$R$26:$U$119,4,FALSE),0)+0 -> 0 | Q28: =+J28/H28 -> 0 | R28: PRODT-0012 | S28: GLUP! FRESH CAJA X 6BOT X 2.0LTS | T28: CAJA | U28: 3476 | V28: 13560 | X28: -13036 | Y28: USD 1,680 | Z28: USD 880,320 | AC28: =+IFERROR(VLOOKUP(T28,$R$24:$U$119,4,FALSE),0) -> 0 | AE28: =18+12+142+96+65 -> 333 | AF28: =+AE28*78 -> 25974 | AG28: =+AF28+34 -> 26008 | AI28: 86 | AJ28: =IFERROR(ROUND((+Q28/AI28),1),0) -> 0
A29: PRODT-0012 | B29: GLUP! FRESH 6X2000ML | H29: 80 | J29: =9958-1+15680 -> 25637 | L29: CJ | M29: =+J29-N29 -> 22161 | N29: =+IFERROR(VLOOKUP(A29,$R$26:$U$119,4,FALSE),0)-0 -> 3476 | O29: =9357-J29 -> -16280 | P29: =J29-IFERROR(VLOOKUP(A29,$R$26:$U$119,4,FALSE),0)+640 -> 22801 | Q29: =+J29/H29 -> 320.4625 | R29: PRODT-0014 | S29: JUSTY NARANJA CAJA X 12BOT X 1.5LTS | T29: CAJA | U29: 40630 | V29: 9830 | X29: 37099 | Y29: USD 2,500 | Z29: USD 117.322,500 | AC29: =+IFERROR(VLOOKUP(T29,$R$24:$U$119,4,FALSE),0)-0-3520-2560-2960-1600-480 -> -11120 | AE29: =7+14+1+24+48+12+15 -> 121 | AF29: =+AE29*160 -> 19360 | AG29: =+AF29+64+133 -> 19557 | AI29: 261 | AJ29: =IFERROR(ROUND((+Q29/AI29),1),0) -> 1.2
A30: PRODT-0048 | B30: GLUP! PONCHE DE FRUTAS CAJA X 6BOT X 2LTS | H30: 80 | J30: 0 | L30: CJ | M30: =+J30-N30 -> 0 | N30: =+IFERROR(VLOOKUP(A30,$R$26:$U$119,4,FALSE),0)-0 -> 0 | P30: =J30-IFERROR(VLOOKUP(A30,$R$26:$U$119,4,FALSE),0)+0 -> 0 | Q30: =+J30/H30 -> 0 | R30: PRODT-0049 | S30: GLUP! MANZANA VERDE CAJA X 6BOT X 2.0 LTS | T30: CAJA | U30: 1 | V30: 80 | X30: -79 | Y30: USD 1,680 | Z30: USD 1,680 | AI30: 0 | AJ30: =IFERROR(ROUND((+Q30/AI30),1),0) -> 0
A31: PRODT-0049 | B31: GLUP! MANZANA VERDE CAJA X 6BOT X 2LTS | H31: 80 | J31: 15612 | L31: CJ | M31: =+J31-N31 -> 15611 | N31: =+IFERROR(VLOOKUP(A31,$R$26:$U$119,4,FALSE),0)-0 -> 1 | O31: =525-J31 -> -15087 | P31: =J31-IFERROR(VLOOKUP(A31,$R$26:$U$119,4,FALSE),0)+0 -> 15611 | Q31: =+J31/H31 -> 195.15 | R31: PRODT-0082 | S31: GLUP! COLA NEGRA CAJA X 12BOT X 1LTS | T31: CAJA | U31: 28310 | V31: 15449 | X31: 10277 | Y31: USD 2,240 | Z31: USD 57.626,240 | AI31: 6 | AJ31: =IFERROR(ROUND((+Q31/AI31),1),0) -> 32.5
A32: PRODT-0050 | B32: GLUP! CHICLE BOMBA CAJA X 6BOT X 2LTS | H32: 80 | J32: 0 | L32: CJ | M32: =+J32-N32 -> 0 | N32: =+IFERROR(VLOOKUP(A32,$R$26:$U$119,4,FALSE),0)-0 -> 0 | P32: =J32-IFERROR(VLOOKUP(A32,$R$26:$U$119,4,FALSE),0)+0 -> 0 | Q32: =+J32/H32 -> 0 | R32: PRODT-0084 | S32: GLUP! UVA CAJA X 12BOT X 1.0LTS | T32: CAJA | U32: 17551 | V32: 1850 | X32: -826 | Y32: USD 2,240 | Z32: USD 2.293,760 | AI32: 0 | AJ32: =IFERROR(ROUND((+Q32/AI32),1),0) -> 0
A33: PRODT-0097 | B33: GLUP! MANZANA ROJA CAJA X 6BOT X 2.0LTS | H33: 80 | J33: =4828+2240 -> 7068 | L33: CJ | M33: =+J33-N33 -> 7068 | N33: =+IFERROR(VLOOKUP(A33,$R$24:$U$119,4,FALSE),0)-0 -> 0 | O33: =0-J33 -> -7068 | P33: =J33-IFERROR(VLOOKUP(A33,$R$24:$U$119,4,FALSE),0)+0 -> 7068 | Q33: =+J33/H33 -> 88.35 | R33: PRODT-0086 | S33: GLUP! FRESH CAJA X 12BOT X 1.0LTS | T33: CAJA | U33: 7845 | V33: 2296 | X33: -2246 | Y33: USD 2,240 | Z33: USD 112,000 | AI33: 60 | AJ33: =IFERROR(ROUND((+Q33/AI33),1),0) -> 1.5
A34: PRODT-0098 | B34: GLUP! PIÑA PARCHITA CAJA X 6BOT X 2.0LTS | H34: 80 | J34: 6075 | L34: CJ | M34: =+J34-N34 -> -44855 | N34: =+IFERROR(VLOOKUP(A34,$R$24:$U$119,4,FALSE),0)-0 -> 50930 | O34: =0-J34 -> -6075 | P34: =J34-IFERROR(VLOOKUP(A34,$R$24:$U$119,4,FALSE),0)+0 -> -44855 | Q34: =+J34/H34 -> 75.9375 | R34: PRODT-0088 | S34: GLUP! KOLITA CAJA X 12BOT X 1.0LTS | T34: CAJA | U34: 23279 | V34: 7587 | X34: 4484 | Y34: USD 2,240 | Z34: USD 27.039,040 | AI34: 6 | AJ34: =IFERROR(ROUND((+Q34/AI34),1),0) -> 12.7
A35: PRODT-0082 | B35: GLUP! COLA NEGRA CAJA X 12BOT X 1LTS | H35: 78 | J35: =7468-2+2184 -> 9650 | L35: CJ | M35: =+J35-N35 -> -18660 | N35: =+IFERROR(VLOOKUP(A35,$R$26:$U$119,4,FALSE),0)-0 -> 28310 | O35: =132941-J35 -> 123291 | P35: =J35-IFERROR(VLOOKUP(A35,$R$26:$U$119,4,FALSE),0)+3198 -> -15462 | Q35: =+J35/H35 -> 123.71795 | R35: PRODT-0092 | S35: GLUP! COLA NEGRA CAJA X 15 BOT X 0.400LTS | T35: CAJA | U35: 47795 | V35: 11855 | X35: -11243 | Y35: USD 1,480 | Z35: USD 905,760 | AI35: 118 | AJ35: =IFERROR(ROUND((+Q35/AI35),1),0) -> 1
A36: PRODT-0084 | B36: GLUP! UVA CAJA X 12BOT X 1.0LTS | H36: 78 | J36: =9679-156 -> 9523 | L36: CJ | M36: =+J36-N36 -> -8028 | N36: =+IFERROR(VLOOKUP(A36,$R$26:$U$119,4,FALSE),0)-0 -> 17551 | O36: =51894-J36 -> 42371 | P36: =J36-IFERROR(VLOOKUP(A36,$R$26:$U$119,4,FALSE),0)+2106 -> -5922 | Q36: =+J36/H36 -> 122.08974 | R36: PRODT-0093 | S36: GLUP! UVA CAJA X 15BOT X 0.400LTS | T36: CAJA | U36: 11103 | V36: 490 | X36: 4270 | Y36: USD 1,480 | Z36: USD 7.044,800 | AI36: 14 | AJ36: =IFERROR(ROUND((+Q36/AI36),1),0) -> 8.7
A37: PRODT-0086 | B37: GLUP! FRESH CAJA X 12BOT X 1.0LTS | H37: 78 | J37: =2888-1+1794 -> 4681 | L37: CJ | M37: =+J37-N37 -> -3164 | N37: =+IFERROR(VLOOKUP(A37,$R$26:$U$119,4,FALSE),0)-0 -> 7845 | O37: =17462-J37 -> 12781 | P37: =J37-IFERROR(VLOOKUP(A37,$R$26:$U$119,4,FALSE),0)+2496 -> -668 | Q37: =+J37/H37 -> 60.012821 | R37: PRODT-0094 | S37: GLUP! KOLITA CAJA X 15BOT X 0.400LTS | T37: CAJA | U37: 2962 | V37: 1260 | X37: -589 | Y37: USD 1,480 | Z37: USD 993,080 | AI37: 49 | AJ37: =IFERROR(ROUND((+Q37/AI37),1),0) -> 1.2
A38: PRODT-0088 | B38: GLUP! KOLITA CAJA X 12BOT X 1.0LTS | H38: 78 | J38: 32342 | L38: CJ | M38: =+J38-N38 -> 9063 | N38: =+IFERROR(VLOOKUP(A38,$R$26:$U$119,4,FALSE),0)-0 -> 23279 | O38: =39597-J38 -> 7255 | P38: =J38-IFERROR(VLOOKUP(A38,$R$26:$U$119,4,FALSE),0)+2652 -> 11715 | Q38: =+J38/H38 -> 414.64103 | R38: PRODT-0095 | S38: GLUP! FRESH CAJA X 15BOT X 0.400LTS | T38: CAJA | U38: 6 | V38: 1155 | X38: -997 | Y38: USD 1,480 | Z38: USD 233,840 | AI38: 45 | AJ38: =IFERROR(ROUND((+Q38/AI38),1),0) -> 9.2
A39: PRODT-0090 | B39: GLUP! MANZANA VERDE CAJA X 12BOT X 1.0LTS | H39: 78 | J39: 0 | L39: CJ | M39: =+J39-N39 -> 0 | N39: =+IFERROR(VLOOKUP(A39,$R$26:$U$119,4,FALSE),0)-0 -> 0 | O39: =50966-J39 -> 50966 | P39: =J39-IFERROR(VLOOKUP(A39,$R$26:$U$119,4,FALSE),0)+702 -> 702 | Q39: =+J39/H39 -> 0 | AI39: 0 | AJ39: =IFERROR(ROUND((+Q39/AI39),1),0) -> 0
A40: PRODT-0104 | B40: GLUP! PIÑA CAJA X 12BOT X 1.0LTS | H40: 78 | J40: =2042-1+11585 -> 13626 | L40: CJ | M40: =+J40-N40 -> 13626 | N40: =+IFERROR(VLOOKUP(A40,$R$26:$U$119,4,FALSE),0)-0 -> 0 | O40: =50966-J40 -> 37340 | P40: =J40-IFERROR(VLOOKUP(A40,$R$26:$U$119,4,FALSE),0)+702 -> 14328 | Q40: =+J40/H40 -> 174.69231 | AI40: 7 | AJ40: =IFERROR(ROUND((+Q40/AI40),1),0) -> 25
...
